[2024-04-23T18:26:48.899+0000] {taskinstance.py:1103} INFO - Dependencies all met for dep_context=non-requeueable deps ti=<TaskInstance: transform_dag.transform_task manual__2024-04-23T18:26:46.790952+00:00 [queued]>
[2024-04-23T18:26:48.904+0000] {taskinstance.py:1103} INFO - Dependencies all met for dep_context=requeueable deps ti=<TaskInstance: transform_dag.transform_task manual__2024-04-23T18:26:46.790952+00:00 [queued]>
[2024-04-23T18:26:48.904+0000] {taskinstance.py:1308} INFO - Starting attempt 1 of 1
[2024-04-23T18:26:48.937+0000] {taskinstance.py:1327} INFO - Executing <Task(PythonOperator): transform_task> on 2024-04-23 18:26:46.790952+00:00
[2024-04-23T18:26:48.941+0000] {standard_task_runner.py:57} INFO - Started process 69929 to run task
[2024-04-23T18:26:48.944+0000] {standard_task_runner.py:84} INFO - Running: ['airflow', 'tasks', 'run', 'transform_dag', 'transform_task', 'manual__2024-04-23T18:26:46.790952+00:00', '--job-id', '2', '--raw', '--subdir', 'DAGS_FOLDER/transform_dag.py', '--cfg-path', '/tmp/tmp4ginqr_d']
[2024-04-23T18:26:48.944+0000] {standard_task_runner.py:85} INFO - Job 2: Subtask transform_task
[2024-04-23T18:26:48.997+0000] {task_command.py:410} INFO - Running <TaskInstance: transform_dag.transform_task manual__2024-04-23T18:26:46.790952+00:00 [running]> on host codespaces-225cfe
[2024-04-23T18:26:49.085+0000] {taskinstance.py:1545} INFO - Exporting env vars: AIRFLOW_CTX_DAG_OWNER='airflow' AIRFLOW_CTX_DAG_ID='transform_dag' AIRFLOW_CTX_TASK_ID='transform_task' AIRFLOW_CTX_EXECUTION_DATE='2024-04-23T18:26:46.790952+00:00' AIRFLOW_CTX_TRY_NUMBER='1' AIRFLOW_CTX_DAG_RUN_ID='manual__2024-04-23T18:26:46.790952+00:00'
[2024-04-23T18:26:49.091+0000] {taskinstance.py:1824} ERROR - Task failed with exception
Traceback (most recent call last):
  File "/usr/local/python/3.10.13/lib/python3.10/site-packages/airflow/operators/python.py", line 181, in execute
    return_value = self.execute_callable()
  File "/usr/local/python/3.10.13/lib/python3.10/site-packages/airflow/operators/python.py", line 198, in execute_callable
    return self.python_callable(*self.op_args, **self.op_kwargs)
  File "/workspaces/hands-on-introduction-data-engineering-4395021/airflow/dags/transform_dag.py", line 20, in transform_data
    generic_type_df.to_csv('/workspaces/hands-on-introduction-data-engineering-4395021/lab/orchestrated/airflow-transform-data.csv', index = False)
AttributeError: 'str' object has no attribute 'to_csv'
[2024-04-23T18:26:49.095+0000] {taskinstance.py:1345} INFO - Marking task as FAILED. dag_id=transform_dag, task_id=transform_task, execution_date=20240423T182646, start_date=20240423T182648, end_date=20240423T182649
[2024-04-23T18:26:49.127+0000] {standard_task_runner.py:104} ERROR - Failed to execute job 2 for task transform_task ('str' object has no attribute 'to_csv'; 69929)
[2024-04-23T18:26:49.156+0000] {local_task_job_runner.py:225} INFO - Task exited with return code 1
[2024-04-23T18:26:49.165+0000] {taskinstance.py:2653} INFO - 0 downstream tasks scheduled from follow-on schedule check
