[2024-04-23T18:27:53.913+0000] {taskinstance.py:1103} INFO - Dependencies all met for dep_context=non-requeueable deps ti=<TaskInstance: transform_dag.transform_task manual__2024-04-23T18:27:51.371554+00:00 [queued]>
[2024-04-23T18:27:53.918+0000] {taskinstance.py:1103} INFO - Dependencies all met for dep_context=requeueable deps ti=<TaskInstance: transform_dag.transform_task manual__2024-04-23T18:27:51.371554+00:00 [queued]>
[2024-04-23T18:27:53.918+0000] {taskinstance.py:1308} INFO - Starting attempt 1 of 1
[2024-04-23T18:27:53.956+0000] {taskinstance.py:1327} INFO - Executing <Task(PythonOperator): transform_task> on 2024-04-23 18:27:51.371554+00:00
[2024-04-23T18:27:53.960+0000] {standard_task_runner.py:57} INFO - Started process 70243 to run task
[2024-04-23T18:27:53.962+0000] {standard_task_runner.py:84} INFO - Running: ['airflow', 'tasks', 'run', 'transform_dag', 'transform_task', 'manual__2024-04-23T18:27:51.371554+00:00', '--job-id', '3', '--raw', '--subdir', 'DAGS_FOLDER/transform_dag.py', '--cfg-path', '/tmp/tmplpocaamd']
[2024-04-23T18:27:53.962+0000] {standard_task_runner.py:85} INFO - Job 3: Subtask transform_task
[2024-04-23T18:27:54.011+0000] {task_command.py:410} INFO - Running <TaskInstance: transform_dag.transform_task manual__2024-04-23T18:27:51.371554+00:00 [running]> on host codespaces-225cfe
[2024-04-23T18:27:54.111+0000] {taskinstance.py:1545} INFO - Exporting env vars: AIRFLOW_CTX_DAG_OWNER='airflow' AIRFLOW_CTX_DAG_ID='transform_dag' AIRFLOW_CTX_TASK_ID='transform_task' AIRFLOW_CTX_EXECUTION_DATE='2024-04-23T18:27:51.371554+00:00' AIRFLOW_CTX_TRY_NUMBER='1' AIRFLOW_CTX_DAG_RUN_ID='manual__2024-04-23T18:27:51.371554+00:00'
[2024-04-23T18:27:54.117+0000] {taskinstance.py:1824} ERROR - Task failed with exception
Traceback (most recent call last):
  File "/usr/local/python/3.10.13/lib/python3.10/site-packages/airflow/operators/python.py", line 181, in execute
    return_value = self.execute_callable()
  File "/usr/local/python/3.10.13/lib/python3.10/site-packages/airflow/operators/python.py", line 198, in execute_callable
    return self.python_callable(*self.op_args, **self.op_kwargs)
  File "/workspaces/hands-on-introduction-data-engineering-4395021/airflow/dags/transform_dag.py", line 20, in transform_data
    generic_type_df.to_csv('/workspaces/hands-on-introduction-data-engineering-4395021/lab/orchestrated/airflow-transform-data.csv', index = False)
AttributeError: 'str' object has no attribute 'to_csv'
[2024-04-23T18:27:54.121+0000] {taskinstance.py:1345} INFO - Marking task as FAILED. dag_id=transform_dag, task_id=transform_task, execution_date=20240423T182751, start_date=20240423T182753, end_date=20240423T182754
[2024-04-23T18:27:54.160+0000] {standard_task_runner.py:104} ERROR - Failed to execute job 3 for task transform_task ('str' object has no attribute 'to_csv'; 70243)
[2024-04-23T18:27:54.174+0000] {local_task_job_runner.py:225} INFO - Task exited with return code 1
[2024-04-23T18:27:54.184+0000] {taskinstance.py:2653} INFO - 0 downstream tasks scheduled from follow-on schedule check
